## 039：例外(1)
* 次のプログラムをコンパイル・実行するとどうなるか？（実際に実行させずに解答すること）

```java
public class Knock039 {
    public static void main(String[] arguments) {
        try {
            try {
                throw new Exception("1st");
            } finally {
                throw new Exception("2nd");
            }
        } catch (Exception happened) {
            System.out.println(happened.getMessage());
        }
    }
}
```


A:  
1st  
2nd  
とエラー表示される。  

→  
finally 節の処理が try の例外処理より優先されるため、finally 節の throw が catch され、 2nd が出力されて終了する。  

//catchできるのは１つだけ。＝最後に投げられた方を受け取った(?)